<mujoco>

  <asset>
    <texture type="skybox" builtin="gradient" rgb1=".3 .5 .7" rgb2="0 0 0" width="512" height="512"/>
    <texture name="body" type="cube" builtin="flat" mark="cross" width="127" height="1278"
             rgb1="0.8 0.6 0.4" rgb2="0.8 0.6 0.4" markrgb="1 1 1" random="0.01"/>
    <material name="body" texture="body" texuniform="true" rgba="0.8 0.6 .4 1"/>
    <texture name="grid" type="2d" builtin="checker" width="512" height="512" rgb1=".1 .2 .3" rgb2=".2 .3 .4"/>
    <material name="grid" texture="grid" texrepeat="1 1" texuniform="true" reflectance=".2"/>
  </asset>

  <default>
    <motor ctrlrange="-3.14159265358979 3.14159265358979" ctrllimited="true"/>
    <default class="body">
      <geom type="capsule" condim="1" friction=".7" solimp=".9 .99 .003" solref=".015 1" material="body"/>
      <joint type="hinge" damping=".2" stiffness="1" armature=".01" limited="true" solimplimit="0 .99 .01"/>
      <default class="big_joint">
        <joint damping="5" stiffness="10"/>
        <default class="big_stiff_joint">
          <joint stiffness="100"/>
        </default>
      </default>
    </default>
  </default>
  
  <visual>
    <map force="0.1" zfar="30"/>
    <rgba haze="0.15 0.25 0.35 1"/>
    <quality shadowsize="4096"/>
    <global offwidth="800" offheight="800"/>
  </visual>

  <option gravity = "0 0 -9.81" />
    <worldbody>
      <light diffuse="0 0 0" pos="0 0 10" dir="0 0 -1"/>
      <geom name="floor" size="0 0 .05" type="plane" material="grid" condim="3"/>
      <body pos = "0 0 0.1" euler="0 0 0">
        <geom type="sphere" size="0.05 0.2" rgba="0 0 1 1" mass = "1"/>
        <joint type = "hinge" name = "joint0"/>
        <body pos = "0 0.2 0" euler="90 0 0">
          <geom type="cylinder" contype="1" mass = "1" size="0.05 0.2" rgba="0 0 1 1"/>
          <site name="center" size="0.001" pos="0 0 -0.2"/>
        </body>
		  </body>
      <body pos = "2 2 0.5">
			  <joint type="free"/>
        <site name="body" size="0.05" pos="0 0 0"/>
			  <geom type="sphere" size=".1 .1 .1" rgba="0.95 0.95 0 1" mass="1"/>
		  </body>
    </worldbody>
    <actuator>
      <motor name="torque" joint="joint0" gear="1" ctrllimited="true" ctrlrange="-100 100"/>
      <position name="position_servo" joint="joint0" kp="0"/>
      <velocity name="velocity_servo" joint="joint0" kv="10"/>
    </actuator>
    <sensor>
      <framepos objtype="site" objname="center"/>
      <framepos objtype="site" objname="body"/>
    </sensor>
</mujoco>
